<?xml version="1.0"?>
<robot name="my_robot" xmlns:xacro="http://www.ros.org/wiki/xacro">

  <material name="blue"><color rgba="0.0 0.0 0.8 1.0"/></material>
  <material name="black"><color rgba="0.0 0.0 0.0 1.0"/></material>
  <material name="white"><color rgba="1.0 1.0 1.0 1.0"/></material>
  <material name="red"><color rgba="1.0 0.0 0.0 1.0"/></material>

  <xacro:macro name="box_inertia" params="m x y z">
    <inertial>
      <mass value="${m}"/>
      <inertia ixx="${(m/12) * (y*y + z*z)}" ixy="0" ixz="0"
               iyy="${(m/12) * (x*x + z*z)}" iyz="0"
               izz="${(m/12) * (x*x + y*y)}" />
    </inertial>
  </xacro:macro>

  <xacro:macro name="cylinder_inertia" params="m r h">
    <inertial>
      <mass value="${m}"/>
      <inertia ixx="${(m/12) * (3*r*r + h*h)}" ixy="0" ixz="0"
               iyy="${(m/12) * (3*r*r + h*h)}" iyz="0"
               izz="${(m/2) * (r*r)}" />
    </inertial>
  </xacro:macro>

  <xacro:macro name="sphere_inertia" params="m r">
    <inertial>
      <mass value="${m}"/>
      <inertia ixx="${(2/5) * m * (r*r)}" ixy="0" ixz="0"
               iyy="${(2/5) * m * (r*r)}" iyz="0"
               izz="${(2/5) * m * (r*r)}" />
    </inertial>
  </xacro:macro>

  <link name="base_footprint"/>
  <joint name="base_joint" type="fixed">
    <parent link="base_footprint"/>
    <child link="base_link"/>
    <origin xyz="0 0 0"/>
  </joint>
  <link name="base_link"/>

  <link name="chassis">
    <visual>
      <geometry><box size="0.5 0.3 0.1"/></geometry>
      <material name="blue"/>
      <origin xyz="0 0 0.1"/>
    </visual>
    <collision>
      <geometry><box size="0.5 0.3 0.1"/></geometry>
      <origin xyz="0 0 0.15"/>
    </collision>
    <xacro:box_inertia m="10.0" x="0.5" y="0.3" z="0.1"/>
  </link>
  <joint name="base_to_chassis" type="fixed">
    <parent link="base_link"/>
    <child link="chassis"/>
  </joint>

  <link name="left_wheel">
    <visual>
      <geometry><cylinder radius="0.05" length="0.04"/></geometry>
      <material name="black"/>
      <origin rpy="1.5708 0 0"/>
    </visual>
    <collision>
      <geometry><sphere radius="0.05"/></geometry> 
      <origin rpy="1.5708 0 0"/>
    </collision>
    <xacro:cylinder_inertia m="2.0" r="0.05" h="0.04"/>
  </link>

  <joint name="left_wheel_joint" type="continuous">
    <parent link="chassis"/>
    <child link="left_wheel"/>
    <origin xyz="-0.15 0.17 0.05"/>
    <axis xyz="0 1 0"/>
  </joint>

  <link name="right_wheel">
    <visual>
      <geometry><cylinder radius="0.05" length="0.04"/></geometry>
      <material name="black"/>
      <origin rpy="1.5708 0 0"/>
    </visual>
    <collision>
      <geometry><sphere radius="0.05"/></geometry>
      <origin rpy="1.5708 0 0"/>
    </collision>
    <xacro:cylinder_inertia m="2.0" r="0.05" h="0.04"/>
  </link>

  <joint name="right_wheel_joint" type="continuous">
    <parent link="chassis"/>
    <child link="right_wheel"/>
    <origin xyz="-0.15 -0.17 0.05"/>
    <axis xyz="0 1 0"/>
  </joint>

  <link name="caster_wheel">
    <visual>
      <geometry><sphere radius="0.05"/></geometry>
      <material name="white"/>
    </visual>
    <collision>
      <geometry><sphere radius="0.05"/></geometry>
    </collision>
    <xacro:sphere_inertia m="1.0" r="0.05"/>
  </link>
  <joint name="caster_joint" type="fixed">
    <parent link="chassis"/>
    <child link="caster_wheel"/>
    <origin xyz="0.15 0 0.05"/>
  </joint>

  <link name="lidar_link">
    <visual>
      <geometry><cylinder radius="0.05" length="0.04"/></geometry>
      <material name="red"/>
    </visual>
    <collision>
      <geometry><cylinder radius="0.05" length="0.04"/></geometry>
    </collision>
    <xacro:cylinder_inertia m="0.1" r="0.05" h="0.04"/>
  </link>
  <joint name="lidar_joint" type="fixed">
    <parent link="chassis"/>
    <child link="lidar_link"/>
    <origin xyz="0 0 0.17"/>
  </joint>

  <gazebo reference="chassis"><material>Gazebo/Blue</material></gazebo>
  <gazebo reference="caster_wheel">
    <material>Gazebo/White</material>
    <mu1>0.001</mu1><mu2>0.001</mu2>
  </gazebo>
  <gazebo reference="left_wheel">
    <material>Gazebo/Black</material>
    <mu1>1.0</mu1><mu2>1.0</mu2>
  </gazebo>
  <gazebo reference="right_wheel">
    <material>Gazebo/Black</material>
    <mu1>1.0</mu1><mu2>1.0</mu2>
  </gazebo>
  <gazebo reference="lidar_link">
    <material>Gazebo/Red</material>
    <sensor name="lidar" type="ray">
      <pose>0 0 0 0 0 0</pose>
      <visualize>true</visualize>
      <update_rate>10</update_rate>
      <ray>
        <scan>
          <horizontal>
            <samples>360</samples><resolution>1</resolution>
            <min_angle>-3.14</min_angle><max_angle>3.14</max_angle>
          </horizontal>
        </scan>
        <range><min>0.3</min><max>12</max></range>
      </ray>
      <plugin name="laser_controller" filename="libgazebo_ros_ray_sensor.so">
        <ros><argument>~/out:=scan</argument></ros>
        <output_type>sensor_msgs/LaserScan</output_type>
        <frame_name>lidar_link</frame_name>
      </plugin>
    </sensor>
  </gazebo>

  <gazebo>
    <plugin name="diff_drive" filename="libgazebo_ros_diff_drive.so">
      <left_joint>left_wheel_joint</left_joint>
      <right_joint>right_wheel_joint</right_joint>
      <wheel_separation>0.34</wheel_separation>
      <wheel_diameter>0.1</wheel_diameter>
      <max_wheel_torque>50</max_wheel_torque>
      <max_wheel_acceleration>1.0</max_wheel_acceleration>
      <odometry_frame>odom</odometry_frame>
      <robot_base_frame>base_footprint</robot_base_frame>
      <publish_odom>true</publish_odom>
      <publish_odom_tf>true</publish_odom_tf>
      <publish_wheel_tf>true</publish_wheel_tf>
      
      <odometry_source>world</odometry_source> 
      
    </plugin>
  </gazebo>

</robot>
